Workbook

Sheet README
A1: SYNTHETIC DEMONSTRATION - not operational, medical or financial guidance
A3: As-of date (drives every formula) | B3: 46319
A5: Licenses hub - Coralline Infusion Network (fictional). Staff are role labels; license IDs are MOCK- and nonfunctional.
A6: Change B3 to re-age every license: Days to expiry and Renewal bucket are live formulas.
A7: Tabs: Clinical licenses | Site licenses | Director coverage | Site compliance | Reminder plan | Exceptions | QA
A8: Reminder plan is a plan only - no reminder automation is deployed.

Sheet Clinical licenses
A1: SYNTHETIC DEMONSTRATION - not operational, medical or financial guidance
A3: Record | B3: Staff (label) | C3: Role | D3: Home site | E3: Credential | F3: Scope | G3: State | H3: License ID (mock) | I3: Issued | J3: Expires | K3: Verified | L3: Recorded status | M3: Doc flag | N3: Docs on file | O3: Days to expiry | P3: Renewal bucket | Q3: Findings
A4: LIC023 | B4: RN-023 (fictional) | C4: Registered nurse | D4: S01 | E4: RN | F4: Multistate (compact, mock) | G4: GA | H4: MOCK-RN-GA-74580 | I4: 45544 | J4: 46274 | K4: 45553 | L4: Active | M4: 1 | N4: 1 | O4: =J4-README!$B$3 | P4: =IF(O4<0,"Expired",IF(O4<=30,"Due in 0-30 days",IF(O4<=60,"Due in 31-60 days",IF(O4<=90,"Due in 61-90 days","Current (90+ days)")))) | Q4: Expired 45 days ago but still recorded Active
A5: LIC029 | B5: RN-029 (fictional) | C5: Registered nurse | D5: S05 | E5: RN | F5: Single-state | G5: SC | H5: MOCK-RN-SC-26751 | I5: 45969 | J5: 46307 | K5: 45983 | L5: Active | M5: 1 | N5: 1 | O5: =J5-README!$B$3 | P5: =IF(O5<0,"Expired",IF(O5<=30,"Due in 0-30 days",IF(O5<=60,"Due in 31-60 days",IF(O5<=90,"Due in 61-90 days","Current (90+ days)")))) | Q5: Expired 12 days ago but still recorded Active
A6: LIC011 | B6: RN-011 (fictional) | C6: Registered nurse | D6: S02 | E6: RN | F6: Multistate (compact, mock) | G6: GA | H6: MOCK-RN-GA-54017 | I6: 45599 | J6: 46329 | K6: 45625 | L6: Active | M6: 1 | N6: 0 | O6: =J6-README!$B$3 | P6: =IF(O6<0,"Expired",IF(O6<=30,"Due in 0-30 days",IF(O6<=60,"Due in 31-60 days",IF(O6<=90,"Due in 61-90 days","Current (90+ days)")))) | Q6: Renewal due in 10 days; Register says a document is on file, but none exists
A7: LIC024 | B7: RN-024 (fictional) | C7: Registered nurse | D7: S08 | E7: RN | F7: Single-state | G7: NC | H7: MOCK-RN-NC-68174 | I7: 45599 | J7: 46329 | K7: 45602 | L7: Active | M7: 1 | N7: 1 | O7: =J7-README!$B$3 | P7: =IF(O7<0,"Expired",IF(O7<=30,"Due in 0-30 days",IF(O7<=60,"Due in 31-60 days",IF(O7<=90,"Due in 61-90 days","Current (90+ days)")))) | Q7: Renewal due in 10 days
A8: LIC042 | B8: MD-042 (fictional) | C8: Physician / medical director | D8: S03 | E8: MD | F8: Single-state | G8: GA | H8: MOCK-MD-GA-34503 | I8: 45615 | J8: 46345 | K8: 45654 | L8: Active | M8: 1 | N8: 1 | O8: =J8-README!$B$3 | P8: =IF(O8<0,"Expired",IF(O8<=30,"Due in 0-30 days",IF(O8<=60,"Due in 31-60 days",IF(O8<=90,"Due in 61-90 days","Current (90+ days)")))) | Q8: Renewal due in 26 days
A9: LIC026 | B9: RN-026 (fictional) | C9: Registered nurse | D9: S06 | E9: RN | F9: Multistate (compact, mock) | G9: SC | H9: MOCK-RN-SC-79559 | I9: 45630 | J9: 46360 | K9: 45663 | L9: Active | M9: 1 | N9: 1 | O9: =J9-README!$B$3 | P9: =IF(O9<0,"Expired",IF(O9<=30,"Due in 0-30 days",IF(O9<=60,"Due in 31-60 days",IF(O9<=90,"Due in 61-90 days","Current (90+ days)")))) | Q9: Renewal due in 41 days
A10: LIC037 | B10: APRN-037 (fictional) | C10: Nurse practitioner | D10: S01 | E10: APRN | F10: Single-state | G10: GA | H10: MOCK-APRN-GA-24212 | I10: 45630 | J10: 46360 | K10: 45631 | L10: Active | M10: 1 | N10: 1 | O10: =J10-README!$B$3 | P10: =IF(O10<0,"Expired",IF(O10<=30,"Due in 0-30 days",IF(O10<=60,"Due in 31-60 days",IF(O10<=90,"Due in 61-90 days","Current (90+ days)")))) | Q10: Renewal due in 41 days
A11: LIC007 | B11: RN-007 (fictional) | C11: Registered nurse | D11: S08 | E11: RN | F11: Multistate (compact, mock) | G11: NC | H11: MOCK-RN-NC-35674 | I11: 45645 | J11: 46375 | K11: 45646 | L11: Active | M11: 1 | N11: 1 | O11: =J11-README!$B$3 | P11: =IF(O11<0,"Expired",IF(O11<=30,"Due in 0-30 days",IF(O11<=60,"Due in 31-60 days",IF(O11<=90,"Due in 61-90 days","Current (90+ days)")))) | Q11: Renewal due in 56 days
A12: LIC036 | B12: APRN-036 (fictional) | C12: Nurse practitioner | D12: S04 | E12: APRN | F12: Single-state | G12: SC | H12: MOCK-APRN-SC-63237 | I12: 45655 | J12: 46385 | K12: 45671 | L12: Active | M12: 1 | N12: 1 | O12: =J12-README!$B$3 | P12: =IF(O12<0,"Expired",IF(O12<=30,"Due in 0-30 days",IF(O12<=60,"Due in 31-60 days",IF(O12<=90,"Due in 61-90 days","Current (90+ days)")))) | Q12: Renewal due in 66 days
A13: LIC020 | B13: RN-020 (fictional) | C13: Registered nurse | D13: S06 | E13: RN | F13: Multistate (compact, mock) | G13: SC | H13: MOCK-RN-SC-28320 | I13: 45658 | J13: 46388 | K13: 45659 | L13: Active | M13: 1 | N13: 1 | O13: =J13-README!$B$3 | P13: =IF(O13<0,"Expired",IF(O13<=30,"Due in 0-30 days",IF(O13<=60,"Due in 31-60 days",IF(O13<=90,"Due in 61-90 days","Current (90+ days)")))) | Q13: Renewal due in 69 days
A14: LIC045 | B14: RN-020 (fictional) | C14: Registered nurse | D14: S06 | E14: RN | F14: Multistate (compact, mock) | G14: SC | H14: MOCK-RN-SC-28320 | I14: 45658 | J14: 46388 | K14: 45659 | L14: Active | M14: 1 | N14: 0 | O14: =J14-README!$B$3 | P14: =IF(O14<0,"Expired",IF(O14<=30,"Due in 0-30 days",IF(O14<=60,"Due in 31-60 days",IF(O14<=90,"Due in 61-90 days","Current (90+ days)")))) | Q14: Duplicate of LIC020 (same license ID)
A15: LIC043 | B15: MD-043 (fictional) | C15: Physician / medical director | D15: S05 | E15: MD | F15: Single-state | G15: SC | H15: MOCK-MD-SC-20776 | I15: 45663 | J15: 46393 | K15: 45680 | L15: Active | M15: 1 | N15: 1 | O15: =J15-README!$B$3 | P15: =IF(O15<0,"Expired",IF(O15<=30,"Due in 0-30 days",IF(O15<=60,"Due in 31-60 days",IF(O15<=90,"Due in 61-90 days","Current (90+ days)")))) | Q15: Renewal due in 74 days
A16: LIC040 | B16: PharmD-040 (fictional) | C16: Pharmacist | D16: S02 | E16: PharmD | F16: Single-state | G16: GA | H16: MOCK-PharmD-GA-96184 | I16: 45676 | J16: 46406 | K16: 45711 | L16: Active | M16: 1 | N16: 1 | O16: =J16-README!$B$3 | P16: =IF(O16<0,"Expired",IF(O16<=30,"Due in 0-30 days",IF(O16<=60,"Due in 31-60 days",IF(O16<=90,"Due in 61-90 days","Current (90+ days)")))) | Q16: Renewal due in 87 days
A17: LIC044 | B17: MD-044 (fictional) | C17: Physician / medical director | D17: S01 | E17: MD | F17: Single-state | G17: GA | H17: MOCK-MD-GA-22507 | I17: 45687 | J17: 46417 | K17: 45710 | L17: Active | M17: 1 | N17: 1 | O17: =J17-README!$B$3 | P17: =IF(O17<0,"Expired",IF(O17<=30,"Due in 0-30 days",IF(O17<=60,"Due in 31-60 days",IF(O17<=90,"Due in 61-90 days","Current (90+ days)"))))
A18: LIC041 | B18: MD-041 (fictional) | C18: Physician / medical director | D18: S08 | E18: MD | F18: Single-state | G18: NC | H18: MOCK-MD-NC-12001 | I18: 45690 | J18: 46420 | K18: 45720 | L18: Active | M18: 1 | N18: 1 | O18: =J18-README!$B$3 | P18: =IF(O18<0,"Expired",IF(O18<=30,"Due in 0-30 days",IF(O18<=60,"Due in 31-60 days",IF(O18<=90,"Due in 61-90 days","Current (90+ days)"))))
A19: LIC001 | B19: RN-001 (fictional) | C19: Registered nurse | D19: S08 | E19: RN | F19: Multistate (compact, mock) | G19: NC | H19: MOCK-RN-NC-92420 | I19: 45698 | J19: 46428 | K19: 45714 | L19: Active | M19: 1 | N19: 1 | O19: =J19-README!$B$3 | P19: =IF(O19<0,"Expired",IF(O19<=30,"Due in 0-30 days",IF(O19<=60,"Due in 31-60 days",IF(O19<=90,"Due in 61-90 days","Current (90+ days)"))))
A20: LIC030 | B20: LPN-030 (fictional) | C20: Licensed practical nurse | D20: S01 | E20: LPN | F20: Multistate (compact, mock) | G20: GA | H20: MOCK-LPN-GA-98471 | I20: 45703 | J20: 46433 | K20: 45717 | L20: Active | M20: 1 | N20: 1 | O20: =J20-README!$B$3 | P20: =IF(O20<0,"Expired",IF(O20<=30,"Due in 0-30 days",IF(O20<=60,"Due in 31-60 days",IF(O20<=90,"Due in 61-90 days","Current (90+ days)"))))
A21: LIC014 | B21: RN-014 (fictional) | C21: Registered nurse | D21: S01 | E21: RN | F21: Multistate (compact, mock) | G21: GA | H21: MOCK-RN-GA-21053 | I21: 45710 | J21: 46440 | K21: 45718 | L21: Active | M21: 1 | N21: 1 | O21: =J21-README!$B$3 | P21: =IF(O21<0,"Expired",IF(O21<=30,"Due in 0-30 days",IF(O21<=60,"Due in 31-60 days",IF(O21<=90,"Due in 61-90 days","Current (90+ days)"))))
A22: LIC021 | B22: RN-021 (fictional) | C22: Registered nurse | D22: S04 | E22: RN | F22: Single-state | G22: SC | H22: MOCK-RN-SC-55415 | I22: 45711 | J22: 46441 | K22: 45717 | L22: Active | M22: 1 | N22: 1 | O22: =J22-README!$B$3 | P22: =IF(O22<0,"Expired",IF(O22<=30,"Due in 0-30 days",IF(O22<=60,"Due in 31-60 days",IF(O22<=90,"Due in 61-90 days","Current (90+ days)"))))
A23: LIC019 | B23: RN-019 (fictional) | C23: Registered nurse | D23: S05 | E23: RN | F23: Multistate (compact, mock) | G23: SC | H23: MOCK-RN-SC-39525 | I23: 45726 | J23: 46456 | K23: 45736 | L23: Active | M23: 1 | N23: 1 | O23: =J23-README!$B$3 | P23: =IF(O23<0,"Expired",IF(O23<=30,"Due in 0-30 days",IF(O23<=60,"Due in 31-60 days",IF(O23<=90,"Due in 61-90 days","Current (90+ days)"))))
A24: LIC016 | B24: RN-016 (fictional) | C24: Registered nurse | D24: S02 | E24: RN | F24: Single-state | G24: GA | H24: MOCK-RN-GA-41622 | I24: 45734 | J24: 46464 | K24: 45767 | L24: Active | M24: 1 | N24: 1 | O24: =J24-README!$B$3 | P24: =IF(O24<0,"Expired",IF(O24<=30,"Due in 0-30 days",IF(O24<=60,"Due in 31-60 days",IF(O24<=90,"Due in 61-90 days","Current (90+ days)"))))
A25: LIC039 | B25: PharmD-039 (fictional) | C25: Pharmacist | D25: S01 | E25: PharmD | F25: Single-state | G25: GA | H25: MOCK-PharmD-GA-76526 | I25: 45747 | J25: 46477 | K25: 45758 | L25: Active | M25: 1 | N25: 1 | O25: =J25-README!$B$3 | P25: =IF(O25<0,"Expired",IF(O25<=30,"Due in 0-30 days",IF(O25<=60,"Due in 31-60 days",IF(O25<=90,"Due in 61-90 days","Current (90+ days)"))))
A26: LIC006 | B26: RN-006 (fictional) | C26: Registered nurse | D26: S06 | E26: RN | F26: Single-state | G26: SC | H26: MOCK-RN-SC-24599 | I26: 45751 | J26: 46481 | K26: 45755 | L26: Active | M26: 1 | N26: 1 | O26: =J26-README!$B$3 | P26: =IF(O26<0,"Expired",IF(O26<=30,"Due in 0-30 days",IF(O26<=60,"Due in 31-60 days",IF(O26<=90,"Due in 61-90 days","Current (90+ days)"))))
A27: LIC018 | B27: RN-018 (fictional) | C27: Registered nurse | D27: S05 | E27: RN | F27: Single-state | G27: SC | H27: MOCK-RN-SC-92323 | I27: 45811 | J27: 46541 | K27: 45812 | L27: Active | M27: 1 | N27: 1 | O27: =J27-README!$B$3 | P27: =IF(O27<0,"Expired",IF(O27<=30,"Due in 0-30 days",IF(O27<=60,"Due in 31-60 days",IF(O27<=90,"Due in 61-90 days","Current (90+ days)"))))
A28: LIC002 | B28: RN-002 (fictional) | C28: Registered nurse | D28: S02 | E28: RN | F28: Single-state | G28: GA | H28: MOCK-RN-GA-54195 | I28: 45877 | J28: 46607 | K28: 45886 | L28: Active | M28: 1 | N28: 1 | O28: =J28-README!$B$3 | P28: =IF(O28<0,"Expired",IF(O28<=30,"Due in 0-30 days",IF(O28<=60,"Due in 31-60 days",IF(O28<=90,"Due in 61-90 days","Current (90+ days)"))))
A29: LIC035 | B29: APRN-035 (fictional) | C29: Nurse practitioner | D29: S03 | E29: APRN | F29: Single-state | G29: GA | H29: MOCK-APRN-GA-48046 | I29: 45903 | J29: 46633 | K29: 45925 | L29: Active | M29: 1 | N29: 1 | O29: =J29-README!$B$3 | P29: =IF(O29<0,"Expired",IF(O29<=30,"Due in 0-30 days",IF(O29<=60,"Due in 31-60 days",IF(O29<=90,"Due in 61-90 days","Current (90+ days)"))))
A30: LIC025 | B30: RN-025 (fictional) | C30: Registered nurse | D30: S04 | E30: RN | F30: Multistate (compact, mock) | G30: SC | H30: MOCK-RN-SC-75857 | I30: 45983 | J30: 46713 | K30: 46004 | L30: Active | M30: 0 | N30: 0 | O30: =J30-README!$B$3 | P30: =IF(O30<0,"Expired",IF(O30<=30,"Due in 0-30 days",IF(O30<=60,"Due in 31-60 days",IF(O30<=90,"Due in 61-90 days","Current (90+ days)")))) | Q30: No license document on file
A31: LIC003 | B31: RN-003 (fictional) | C31: Registered nurse | D31: S05 | E31: RN | F31: Multistate (compact, mock) | G31: SC | H31: MOCK-RN-SC-15209 | I31: 45993 | J31: 46723 | K31: 46012 | L31: Active | M31: 1 | N31: 1 | O31: =J31-README!$B$3 | P31: =IF(O31<0,"Expired",IF(O31<=30,"Due in 0-30 days",IF(O31<=60,"Due in 31-60 days",IF(O31<=90,"Due in 61-90 days","Current (90+ days)"))))
A32: LIC022 | B32: RN-022 (fictional) | C32: Registered nurse | D32: S05 | E32: RN | F32: Single-state | G32: SC | H32: MOCK-RN-SC-31223 | I32: 46014 | J32: 46744 | K32: 46018 | L32: Active | M32: 1 | N32: 1 | O32: =J32-README!$B$3 | P32: =IF(O32<0,"Expired",IF(O32<=30,"Due in 0-30 days",IF(O32<=60,"Due in 31-60 days",IF(O32<=90,"Due in 61-90 days","Current (90+ days)"))))
A33: LIC033 | B33: LPN-033 (fictional) | C33: Licensed practical nurse | D33: S01 | E33: LPN | F33: Single-state | G33: GA | H33: MOCK-LPN-GA-42532 | I33: 46020 | J33: 46750 | K33: 46059 | L33: Active | M33: 1 | N33: 1 | O33: =J33-README!$B$3 | P33: =IF(O33<0,"Expired",IF(O33<=30,"Due in 0-30 days",IF(O33<=60,"Due in 31-60 days",IF(O33<=90,"Due in 61-90 days","Current (90+ days)"))))
A34: LIC015 | B34: RN-015 (fictional) | C34: Registered nurse | D34: S01 | E34: RN | F34: Multistate (compact, mock) | G34: GA | H34: MOCK-RN-GA-23160 | I34: 46021 | J34: 46751 | K34: 46047 | L34: Active | M34: 1 | N34: 1 | O34: =J34-README!$B$3 | P34: =IF(O34<0,"Expired",IF(O34<=30,"Due in 0-30 days",IF(O34<=60,"Due in 31-60 days",IF(O34<=90,"Due in 61-90 days","Current (90+ days)"))))
A35: LIC031 | B35: LPN-031 (fictional) | C35: Licensed practical nurse | D35: S06 | E35: LPN | F35: Single-state | G35: SC | H35: MOCK-LPN-SC-83805 | I35: 46026 | J35: 46756 | K35: 46048 | L35: Active | M35: 1 | N35: 1 | O35: =J35-README!$B$3 | P35: =IF(O35<0,"Expired",IF(O35<=30,"Due in 0-30 days",IF(O35<=60,"Due in 31-60 days",IF(O35<=90,"Due in 61-90 days","Current (90+ days)"))))
A36: LIC004 | B36: RN-004 (fictional) | C36: Registered nurse | D36: S02 | E36: RN | F36: Single-state | G36: GA | H36: MOCK-RN-GA-85780 | I36: 46028 | J36: 46758 | K36: 46057 | L36: Active | M36: 1 | N36: 1 | O36: =J36-README!$B$3 | P36: =IF(O36<0,"Expired",IF(O36<=30,"Due in 0-30 days",IF(O36<=60,"Due in 31-60 days",IF(O36<=90,"Due in 61-90 days","Current (90+ days)"))))
A37: LIC032 | B37: LPN-032 (fictional) | C37: Licensed practical nurse | D37: S04 | E37: LPN | F37: Single-state | G37: SC | H37: MOCK-LPN-SC-74797 | I37: 46032 | J37: 46762 | K37: 46040 | L37: Active | M37: 1 | N37: 1 | O37: =J37-README!$B$3 | P37: =IF(O37<0,"Expired",IF(O37<=30,"Due in 0-30 days",IF(O37<=60,"Due in 31-60 days",IF(O37<=90,"Due in 61-90 days","Current (90+ days)"))))
A38: LIC013 | B38: RN-013 (fictional) | C38: Registered nurse | D38: S07 | E38: RN | F38: Multistate (compact, mock) | G38: NC | H38: MOCK-RN-NC-95019 | I38: 46056 | J38: 46786 | K38: 46069 | L38: Active | M38: 1 | N38: 1 | O38: =J38-README!$B$3 | P38: =IF(O38<0,"Expired",IF(O38<=30,"Due in 0-30 days",IF(O38<=60,"Due in 31-60 days",IF(O38<=90,"Due in 61-90 days","Current (90+ days)"))))
A39: LIC005 | B39: RN-005 (fictional) | C39: Registered nurse | D39: S06 | E39: RN | F39: Multistate (compact, mock) | G39: SC | H39: MOCK-RN-SC-79156 | I39: 46086 | J39: 46816 | K39: 46114 | L39: Active | M39: 1 | N39: 0 | O39: =J39-README!$B$3 | P39: =IF(O39<0,"Expired",IF(O39<=30,"Due in 0-30 days",IF(O39<=60,"Due in 31-60 days",IF(O39<=90,"Due in 61-90 days","Current (90+ days)")))) | Q39: Register says a document is on file, but none exists
A40: LIC028 | B40: RN-028 (fictional) | C40: Registered nurse | D40: S06 | E40: RN | F40: Single-state | G40: SC | H40: MOCK-RN-SC-88344 | I40: 46101 | J40: 46831 | K40: 46123 | L40: Active | M40: 1 | N40: 1 | O40: =J40-README!$B$3 | P40: =IF(O40<0,"Expired",IF(O40<=30,"Due in 0-30 days",IF(O40<=60,"Due in 31-60 days",IF(O40<=90,"Due in 61-90 days","Current (90+ days)"))))
A41: LIC034 | B41: APRN-034 (fictional) | C41: Nurse practitioner | D41: S01 | E41: APRN | F41: Single-state | G41: GA | H41: MOCK-APRN-GA-13945 | I41: 46143 | J41: 46873 | K41: 46178 | L41: Active | M41: 1 | N41: 1 | O41: =J41-README!$B$3 | P41: =IF(O41<0,"Expired",IF(O41<=30,"Due in 0-30 days",IF(O41<=60,"Due in 31-60 days",IF(O41<=90,"Due in 61-90 days","Current (90+ days)"))))
...

Sheet Site licenses
A1: SYNTHETIC DEMONSTRATION - not operational, medical or financial guidance
A3: Record | B3: Site | C3: License type | D3: License ID (mock) | E3: State | F3: Issued | G3: Expires | H3: Doc flag | I3: Days to expiry | J3: Renewal bucket | K3: Findings
A4: SLC001 | B4: Saltmeadow Infusion Suite | C4: Ambulatory infusion center license (mock) | D4: MOCK-AIC-GA-4435 | E4: GA | F4: 46129 | G4: 46859 | H4: 1 | I4: =G4-README!$B$3 | J4: =IF(I4<0,"Expired",IF(I4<=30,"Due in 0-30 days",IF(I4<=60,"Due in 31-60 days",IF(I4<=90,"Due in 61-90 days","Current (90+ days)"))))
A5: SLC002 | B5: Saltmeadow Infusion Suite | C5: Pharmacy permit (mock) | D5: MOCK-PHA-GA-9536 | E5: GA | F5: 45698 | G5: 46428 | H5: 1 | I5: =G5-README!$B$3 | J5: =IF(I5<0,"Expired",IF(I5<=30,"Due in 0-30 days",IF(I5<=60,"Due in 31-60 days",IF(I5<=90,"Due in 61-90 days","Current (90+ days)"))))
A6: SLC003 | B6: Cypressmoor Infusion Suite | C6: Ambulatory infusion center license (mock) | D6: MOCK-AIC-GA-3549 | E6: GA | F6: 45834 | G6: 46564 | H6: 1 | I6: =G6-README!$B$3 | J6: =IF(I6<0,"Expired",IF(I6<=30,"Due in 0-30 days",IF(I6<=60,"Due in 31-60 days",IF(I6<=90,"Due in 61-90 days","Current (90+ days)"))))
A7: SLC004 | B7: Cypressmoor Infusion Suite | C7: Pharmacy permit (mock) | D7: MOCK-PHA-GA-2772 | E7: GA | F7: 45998 | G7: 46360 | H7: 1 | I7: =G7-README!$B$3 | J7: =IF(I7<0,"Expired",IF(I7<=30,"Due in 0-30 days",IF(I7<=60,"Due in 31-60 days",IF(I7<=90,"Due in 61-90 days","Current (90+ days)")))) | K7: Renewal due in 41 days
A8: SLC005 | B8: Larkspur Infusion Suite | C8: Ambulatory infusion center license (mock) | D8: MOCK-AIC-GA-2500 | E8: GA | F8: 45978 | G8: 46708 | H8: 1 | I8: =G8-README!$B$3 | J8: =IF(I8<0,"Expired",IF(I8<=30,"Due in 0-30 days",IF(I8<=60,"Due in 31-60 days",IF(I8<=90,"Due in 61-90 days","Current (90+ days)"))))
A9: SLC006 | B9: Larkspur Infusion Suite | C9: Pharmacy permit (mock) | D9: MOCK-PHA-GA-6068 | E9: GA | F9: 46097 | G9: 46827 | H9: 1 | I9: =G9-README!$B$3 | J9: =IF(I9<0,"Expired",IF(I9<=30,"Due in 0-30 days",IF(I9<=60,"Due in 31-60 days",IF(I9<=90,"Due in 61-90 days","Current (90+ days)"))))
A10: SLC007 | B10: Heronmouth Infusion Suite | C10: Ambulatory infusion center license (mock) | D10: MOCK-AIC-SC-3576 | E10: SC | F10: 46158 | G10: 46888 | H10: 1 | I10: =G10-README!$B$3 | J10: =IF(I10<0,"Expired",IF(I10<=30,"Due in 0-30 days",IF(I10<=60,"Due in 31-60 days",IF(I10<=90,"Due in 61-90 days","Current (90+ days)"))))
A11: SLC008 | B11: Heronmouth Infusion Suite | C11: Pharmacy permit (mock) | D11: MOCK-PHA-SC-8088 | E11: SC | F11: 46143 | G11: 46873 | H11: 1 | I11: =G11-README!$B$3 | J11: =IF(I11<0,"Expired",IF(I11<=30,"Due in 0-30 days",IF(I11<=60,"Due in 31-60 days",IF(I11<=90,"Due in 61-90 days","Current (90+ days)"))))
A12: SLC009 | B12: Sablecrest Infusion Suite | C12: Ambulatory infusion center license (mock) | D12: MOCK-AIC-SC-6059 | E12: SC | F12: 45760 | G12: 46490 | H12: 1 | I12: =G12-README!$B$3 | J12: =IF(I12<0,"Expired",IF(I12<=30,"Due in 0-30 days",IF(I12<=60,"Due in 31-60 days",IF(I12<=90,"Due in 61-90 days","Current (90+ days)"))))
A13: SLC010 | B13: Sablecrest Infusion Suite | C13: Pharmacy permit (mock) | D13: MOCK-PHA-SC-3620 | E13: SC | F13: 45958 | G13: 46688 | H13: 1 | I13: =G13-README!$B$3 | J13: =IF(I13<0,"Expired",IF(I13<=30,"Due in 0-30 days",IF(I13<=60,"Due in 31-60 days",IF(I13<=90,"Due in 61-90 days","Current (90+ days)"))))
A14: SLC011 | B14: Gullwing Infusion Suite | C14: Ambulatory infusion center license (mock) | D14: MOCK-AIC-SC-1184 | E14: SC | F14: 46243 | G14: 46973 | H14: 1 | I14: =G14-README!$B$3 | J14: =IF(I14<0,"Expired",IF(I14<=30,"Due in 0-30 days",IF(I14<=60,"Due in 31-60 days",IF(I14<=90,"Due in 61-90 days","Current (90+ days)"))))
A15: SLC012 | B15: Gullwing Infusion Suite | C15: Pharmacy permit (mock) | D15: MOCK-PHA-SC-5542 | E15: SC | F15: 46190 | G15: 46299 | H15: 1 | I15: =G15-README!$B$3 | J15: =IF(I15<0,"Expired",IF(I15<=30,"Due in 0-30 days",IF(I15<=60,"Due in 31-60 days",IF(I15<=90,"Due in 61-90 days","Current (90+ days)")))) | K15: Expired 20 days ago
A16: SLC013 | B16: Brinemoor Infusion Suite | C16: Ambulatory infusion center license (mock) | D16: MOCK-AIC-NC-1997 | E16: NC | F16: 45858 | G16: 46588 | H16: 1 | I16: =G16-README!$B$3 | J16: =IF(I16<0,"Expired",IF(I16<=30,"Due in 0-30 days",IF(I16<=60,"Due in 31-60 days",IF(I16<=90,"Due in 61-90 days","Current (90+ days)"))))
A17: SLC014 | B17: Brinemoor Infusion Suite | C17: Pharmacy permit (mock) | D17: MOCK-PHA-NC-4046 | E17: NC | F17: 45935 | G17: 46665 | H17: 1 | I17: =G17-README!$B$3 | J17: =IF(I17<0,"Expired",IF(I17<=30,"Due in 0-30 days",IF(I17<=60,"Due in 31-60 days",IF(I17<=90,"Due in 61-90 days","Current (90+ days)"))))
A18: SLC015 | B18: Cedar Landing Infusion Suite | C18: Ambulatory infusion center license (mock) | D18: MOCK-AIC-NC-4112 | E18: NC | F18: 46087 | G18: 46817 | H18: 0 | I18: =G18-README!$B$3 | J18: =IF(I18<0,"Expired",IF(I18<=30,"Due in 0-30 days",IF(I18<=60,"Due in 31-60 days",IF(I18<=90,"Due in 61-90 days","Current (90+ days)")))) | K18: No document on file
A19: SLC016 | B19: Cedar Landing Infusion Suite | C19: Pharmacy permit (mock) | D19: MOCK-PHA-NC-5035 | E19: NC | F19: 45906 | G19: 46636 | H19: 1 | I19: =G19-README!$B$3 | J19: =IF(I19<0,"Expired",IF(I19<=30,"Due in 0-30 days",IF(I19<=60,"Due in 31-60 days",IF(I19<=90,"Due in 61-90 days","Current (90+ days)"))))

Sheet Director coverage
A1: SYNTHETIC DEMONSTRATION - not operational, medical or financial guidance
A3: Assignment | B3: Site | C3: Site name | D3: Director (label) | E3: Start | F3: End | G3: Primary | H3: Current?
A4: MDA001 | B4: S01 | C4: Saltmeadow Infusion Suite | D4: MD-041 (fictional) | E4: 43528 | G4: 1 | H4: =AND(E4<=README!$B$3,OR(F4="",F4>=README!$B$3))
A5: MDA002 | B5: S02 | C5: Cypressmoor Infusion Suite | D5: MD-042 (fictional) | E5: 43983 | G5: 1 | H5: =AND(E5<=README!$B$3,OR(F5="",F5>=README!$B$3))
A6: MDA003 | B6: S03 | C6: Larkspur Infusion Suite | D6: MD-041 (fictional) | E6: 44571 | F6: 45838 | G6: 1 | H6: =AND(E6<=README!$B$3,OR(F6="",F6>=README!$B$3))
A7: MDA004 | B7: S03 | C7: Larkspur Infusion Suite | D7: MD-043 (fictional) | E7: 45839 | G7: 1 | H7: =AND(E7<=README!$B$3,OR(F7="",F7>=README!$B$3))
A8: MDA005 | B8: S04 | C8: Heronmouth Infusion Suite | D8: MD-042 (fictional) | E8: 43360 | G8: 1 | H8: =AND(E8<=README!$B$3,OR(F8="",F8>=README!$B$3))
A9: MDA006 | B9: S05 | C9: Sablecrest Infusion Suite | D9: MD-044 (fictional) | E9: 44291 | F9: 46295 | G9: 1 | H9: =AND(E9<=README!$B$3,OR(F9="",F9>=README!$B$3))
A10: MDA007 | B10: S06 | C10: Gullwing Infusion Suite | D10: MD-043 (fictional) | E10: 44963 | G10: 1 | H10: =AND(E10<=README!$B$3,OR(F10="",F10>=README!$B$3))
A11: MDA008 | B11: S07 | C11: Brinemoor Infusion Suite | D11: MD-044 (fictional) | E11: 43773 | G11: 1 | H11: =AND(E11<=README!$B$3,OR(F11="",F11>=README!$B$3))
A12: MDA010 | B12: S08 | C12: Cedar Landing Infusion Suite | D12: MD-041 (fictional) | E12: 45901 | F12: 46022 | G12: 1 | H12: =AND(E12<=README!$B$3,OR(F12="",F12>=README!$B$3))
A13: MDA009 | B13: S08 | C13: Cedar Landing Infusion Suite | D13: MD-043 (fictional) | E13: 45915 | G13: 1 | H13: =AND(E13<=README!$B$3,OR(F13="",F13>=README!$B$3))

Sheet Site compliance
A1: SYNTHETIC DEMONSTRATION - not operational, medical or financial guidance
A3: Site | B3: Site name | C3: Director today | D3: Infusion center license current | E3: Pharmacy permit current | F3: Site documents on file | G3: Primary medical director today | H3: One primary director at a time | I3: Director license current and documented | J3: Staff licenses current | K3: Staff documents complete | L3: Score
A4: S01 | B4: Saltmeadow Infusion Suite | C4: MD-041 (fictional) | D4: PASS | E4: PASS | F4: PASS | G4: PASS | H4: PASS | I4: PASS | J4: FAIL | K4: PASS | L4: 7/8
A5: S02 | B5: Cypressmoor Infusion Suite | C5: MD-042 (fictional) | D5: PASS | E5: PASS | F5: PASS | G5: PASS | H5: PASS | I5: PASS | J5: PASS | K5: FAIL | L5: 7/8
A6: S03 | B6: Larkspur Infusion Suite | C6: MD-043 (fictional) | D6: PASS | E6: PASS | F6: PASS | G6: PASS | H6: PASS | I6: PASS | J6: PASS | K6: PASS | L6: 8/8
A7: S04 | B7: Heronmouth Infusion Suite | C7: MD-042 (fictional) | D7: PASS | E7: PASS | F7: PASS | G7: PASS | H7: PASS | I7: PASS | J7: PASS | K7: FAIL | L7: 7/8
A8: S05 | B8: Sablecrest Infusion Suite | C8: None | D8: PASS | E8: PASS | F8: PASS | G8: FAIL | H8: PASS | I8: FAIL | J8: FAIL | K8: PASS | L8: 5/8
A9: S06 | B9: Gullwing Infusion Suite | C9: MD-043 (fictional) | D9: PASS | E9: FAIL | F9: PASS | G9: PASS | H9: PASS | I9: PASS | J9: PASS | K9: FAIL | L9: 6/8
A10: S07 | B10: Brinemoor Infusion Suite | C10: MD-044 (fictional) | D10: PASS | E10: PASS | F10: PASS | G10: PASS | H10: PASS | I10: PASS | J10: PASS | K10: PASS | L10: 8/8
A11: S08 | B11: Cedar Landing Infusion Suite | C11: MD-043 (fictional) | D11: PASS | E11: PASS | F11: FAIL | G11: PASS | H11: FAIL | I11: PASS | J11: PASS | K11: PASS | L11: 6/8

Sheet Reminder plan
A1: SYNTHETIC DEMONSTRATION - not operational, medical or financial guidance
A3: Record | B3: Holder | C3: License | D3: Expires | E3: Reminder | F3: Reminder date | G3: Plan status | H3: Note
A4: LIC011 | B4: RN-011 (fictional) | C4: RN | D4: 2026-11-03 | E4: 90-day | F4: 2026-08-05 | G4: Would already have been sent | H4: Plan only - reminder automation not deployed
A5: LIC024 | B5: RN-024 (fictional) | C5: RN | D5: 2026-11-03 | E5: 90-day | F5: 2026-08-05 | G5: Would already have been sent | H5: Plan only - reminder automation not deployed
A6: LIC042 | B6: MD-042 (fictional) | C6: MD | D6: 2026-11-19 | E6: 90-day | F6: 2026-08-21 | G6: Would already have been sent | H6: Plan only - reminder automation not deployed
A7: LIC011 | B7: RN-011 (fictional) | C7: RN | D7: 2026-11-03 | E7: 60-day | F7: 2026-09-04 | G7: Would already have been sent | H7: Plan only - reminder automation not deployed
A8: LIC024 | B8: RN-024 (fictional) | C8: RN | D8: 2026-11-03 | E8: 60-day | F8: 2026-09-04 | G8: Would already have been sent | H8: Plan only - reminder automation not deployed
A9: LIC026 | B9: RN-026 (fictional) | C9: RN | D9: 2026-12-04 | E9: 90-day | F9: 2026-09-05 | G9: Would already have been sent | H9: Plan only - reminder automation not deployed
A10: LIC037 | B10: APRN-037 (fictional) | C10: APRN | D10: 2026-12-04 | E10: 90-day | F10: 2026-09-05 | G10: Would already have been sent | H10: Plan only - reminder automation not deployed
A11: SLC004 | B11: Cypressmoor Infusion Suite | C11: Pharmacy permit (mock) | D11: 2026-12-04 | E11: 90-day | F11: 2026-09-05 | G11: Would already have been sent | H11: Plan only - reminder automation not deployed
A12: LIC007 | B12: RN-007 (fictional) | C12: RN | D12: 2026-12-19 | E12: 90-day | F12: 2026-09-20 | G12: Would already have been sent | H12: Plan only - reminder automation not deployed
A13: LIC042 | B13: MD-042 (fictional) | C13: MD | D13: 2026-11-19 | E13: 60-day | F13: 2026-09-20 | G13: Would already have been sent | H13: Plan only - reminder automation not deployed
A14: LIC036 | B14: APRN-036 (fictional) | C14: APRN | D14: 2026-12-29 | E14: 90-day | F14: 2026-09-30 | G14: Would already have been sent | H14: Plan only - reminder automation not deployed
... A72: SLC009 | B72: Sablecrest Infusion Suite | C72: Ambulatory infusion center license (mock) | D72: 2027-04-13 | E72: 30-day | F72: 2027-03-14 | G72: Scheduled | H72: Plan only - reminder automation not deployed

Sheet Exceptions
A1: SYNTHETIC DEMONSTRATION - not operational, medical or financial guidance
A3: Area | B3: Record | C3: Holder | D3: Code | E3: Finding | F3: Owner | G3: Severity
A4: Nursing & clinical licenses | B4: LIC023 | C4: RN-023 (fictional) | D4: EXPIRED_STATUS_STALE | E4: Expired 45 days ago but still recorded Active | F4: HR / credentialing | G4: High
A5: Nursing & clinical licenses | B5: LIC029 | C5: RN-029 (fictional) | D5: EXPIRED_STATUS_STALE | E5: Expired 12 days ago but still recorded Active | F5: HR / credentialing | G5: High
A6: Nursing & clinical licenses | B6: LIC011 | C6: RN-011 (fictional) | D6: DOC_FLAG_WRONG | E6: Register says a document is on file, but none exists | F6: HR / credentialing | G6: Medium
A7: Nursing & clinical licenses | B7: LIC045 | C7: RN-020 (fictional) | D7: DUPLICATE | E7: Duplicate of LIC020 (same license ID) | F7: HR / credentialing | G7: Medium
A8: Nursing & clinical licenses | B8: LIC025 | C8: RN-025 (fictional) | D8: DOC_MISSING | E8: No license document on file | F8: HR / credentialing | G8: Medium
A9: Nursing & clinical licenses | B9: LIC005 | C9: RN-005 (fictional) | D9: DOC_FLAG_WRONG | E9: Register says a document is on file, but none exists | F9: HR / credentialing | G9: Medium
A10: Nursing & clinical licenses | B10: LIC008 | C10: RN-008 (fictional) | D10: DOC_MISSING | E10: No license document on file | F10: HR / credentialing | G10: Medium
A11: Location licenses | B11: SLC012 | C11: Gullwing Infusion Suite | D11: EXPIRED | E11: Pharmacy permit (mock): Expired 20 days ago | F11: Site operations | G11: High
A12: Location licenses | B12: SLC015 | C12: Cedar Landing Infusion Suite | D12: DOC_MISSING | E12: Ambulatory infusion center license (mock): No document on file | F12: Site operations | G12: Medium
A13: Medical director coverage | B13: MDA009|MDA010 | C13: S08 | D13: MD_OVERLAP | E13: Two primary directors overlap (2025-09-15 to 2025-12-31) | F13: Medical affairs | G13: Medium
A14: Medical director coverage | B14: MDA006 | C14: S05 | D14: MD_UNCOVERED | E14: No active primary medical director since 2026-09-30 | F14: Medical affairs | G14: High

Sheet QA
A1: SYNTHETIC DEMONSTRATION - not operational, medical or financial guidance
A3: Status | B3: Check | C3: Observed | D3: Rule
A4: PASS | B4: Every planted compliance defect is found, nothing extra | C4: 11 exceptions across staff, site and director records; mismatched codes: none | D4: Graded against the ground-truth register
A5: WARN | B5: Status computed from dates, not trusted from the register | C5: 2 license(s) past expiry still typed as Active: LIC023, LIC029 | D5: Status = f(expiry_date, as-of date)
A6: WARN | B6: One row per license | C6: 45 register rows -> 44 unique licenses; duplicates excluded from counts and reminders | D6: Deduplicate on license ID
A7: WARN | B7: Document presence audited against the index | C7: 4 license(s) lack a filed document (2 where the flag wrongly says one exists) | D7: Flag and index must agree
A8: WARN | B8: Every site has exactly one primary medical director | C8: 7/8 sites covered today; one historical overlap of two primaries | D8: Effective intervals may not overlap for primaries
A9: PASS | B9: Renewal buckets are complete and exclusive | C9: Expired: 2, Due in 0-30 days: 3, Due in 31-60 days: 3, Due in 61-90 days: 4, Current (90+ days): 32 | D9: Each license in exactly one 30/60/90 bucket
A10: PASS | B10: Reminder automation is planned, not claimed | C10: 69 reminder dates planned for licenses expiring within 180 days; none sent | D10: Never describe a plan as deployed
A11: PASS | B11: Only nonfunctional MOCK- license IDs and role labels | C11: No names, real license numbers, scans or addresses exist in the data | D11: Public-safe by construction
